[I 2024-02-19 12:08:50.488 ServerApp] jupyter_lsp | extension was successfully linked.
[I 2024-02-19 12:08:50.496 ServerApp] jupyter_server_terminals | extension was successfully linked.
[I 2024-02-19 12:08:50.505 ServerApp] jupyterlab | extension was successfully linked.
[I 2024-02-19 12:08:51.120 ServerApp] notebook_shim | extension was successfully linked.
[I 2024-02-19 12:08:51.199 ServerApp] notebook_shim | extension was successfully loaded.
[I 2024-02-19 12:08:51.203 ServerApp] jupyter_lsp | extension was successfully loaded.
[I 2024-02-19 12:08:51.205 ServerApp] jupyter_server_terminals | extension was successfully loaded.
[I 2024-02-19 12:08:51.214 LabApp] JupyterLab extension loaded from /home/jaalzate/.local/lib/python3.10/site-packages/jupyterlab
[I 2024-02-19 12:08:51.214 LabApp] JupyterLab application directory is /clinicfs/userhomes/jaalzate/.local/share/jupyter/lab
[I 2024-02-19 12:08:51.215 LabApp] Extension Manager is 'pypi'.
[I 2024-02-19 12:08:51.236 ServerApp] jupyterlab | extension was successfully loaded.
[I 2024-02-19 12:08:51.236 ServerApp] Serving notebooks from local directory: /clinicfs/userhomes/jaalzate
[I 2024-02-19 12:08:51.236 ServerApp] Jupyter Server 2.12.5 is running at:
[I 2024-02-19 12:08:51.236 ServerApp] http://gpuceib01:8888/lab
[I 2024-02-19 12:08:51.236 ServerApp]     http://127.0.0.1:8888/lab
[I 2024-02-19 12:08:51.236 ServerApp] Use Control-C to stop this server and shut down all kernels (twice to skip confirmation).
[I 2024-02-19 12:08:51.342 ServerApp] Skipped non-installed server(s): bash-language-server, dockerfile-language-server-nodejs, javascript-typescript-langserver, jedi-language-server, julia-language-server, pyright, python-language-server, python-lsp-server, r-languageserver, sql-language-server, texlab, typescript-language-server, unified-language-server, vscode-css-languageserver-bin, vscode-html-languageserver-bin, vscode-json-languageserver-bin, yaml-language-server
Unable to connect to VS Code server: Error in request.
Error: connect ENOENT /run/user/8065/vscode-ipc-c069e0db-576c-466f-bdf8-9450f045672e.sock
    at PipeConnectWrap.afterConnect [as oncomplete] (node:net:1494:16) {
  errno: -2,
  code: 'ENOENT',
  syscall: 'connect',
  address: '/run/user/8065/vscode-ipc-c069e0db-576c-466f-bdf8-9450f045672e.sock'
}
[W 2024-02-19 12:09:14.769 ServerApp] 404 GET /hub/api (@172.24.79.160) 32.49ms referer=None
[I 2024-02-19 12:09:14.887 ServerApp] Kernel started: 3db022ca-f909-4556-af49-c42e19df514b
[I 2024-02-19 12:09:16.364 ServerApp] Connecting to kernel 3db022ca-f909-4556-af49-c42e19df514b.
old shape: (28, 512, 512), new_shape: [ 27 341 341], old_spacing: [3.0, 0.3125, 0.3125], new_spacing: [3.089737057685852, 0.46875, 0.46875], fn_data: functools.partial(<function resample_data_or_seg_to_shape at 0x7fe900f50e50>, is_seg=False, order=3, order_z=0, force_separate_z=None)
old shape: (28, 512, 512), new_shape: [ 27 341 341], old_spacing: [3.0, 0.3125, 0.3125], new_spacing: [3.089737057685852, 0.46875, 0.46875], fn_data: functools.partial(<function resample_data_or_seg_to_shape at 0x7f4a9e904e50>, is_seg=False, order=3, order_z=0, force_separate_z=None)
old shape: (26, 512, 512), new_shape: [ 25 341 341], old_spacing: [3.0, 0.3125, 0.3125], new_spacing: [3.089737057685852, 0.46875, 0.46875], fn_data: functools.partial(<function resample_data_or_seg_to_shape at 0x7f7169cbce50>, is_seg=False, order=3, order_z=0, force_separate_z=None)
old shape: (24, 308, 308), new_shape: [ 23 205 205], old_spacing: [3.0, 0.3125, 0.3125], new_spacing: [3.089737057685852, 0.46875, 0.46875], fn_data: functools.partial(<function resample_data_or_seg_to_shape at 0x7fbd5b0f4e50>, is_seg=False, order=3, order_z=0, force_separate_z=None)
old shape: (26, 308, 308), new_shape: [ 25 205 205], old_spacing: [3.0, 0.3125, 0.3125], new_spacing: [3.089737057685852, 0.46875, 0.46875], fn_data: functools.partial(<function resample_data_or_seg_to_shape at 0x7f59d8170e50>, is_seg=False, order=3, order_z=0, force_separate_z=None)
old shape: (36, 308, 308), new_shape: [ 35 257 257], old_spacing: [3.0, 0.3905999958515167, 0.3905999958515167], new_spacing: [3.089737057685852, 0.46875, 0.46875], fn_data: functools.partial(<function resample_data_or_seg_to_shape at 0x7fe3ea11ce50>, is_seg=False, order=3, order_z=0, force_separate_z=None)
[I 2024-02-19 14:30:19.646 ServerApp] Starting buffering for 3db022ca-f909-4556-af49-c42e19df514b:d79911ea-ab8d-43e4-96f5-0ad0d5cf3978
[W 2024-02-20 08:28:42.920 ServerApp] 404 GET /hub/api (@172.24.79.160) 36.72ms referer=None
[W 2024-02-20 08:28:42.933 ServerApp] 404 GET /hub/api (@172.24.79.160) 48.23ms referer=None
[W 2024-02-20 08:28:42.935 ServerApp] 404 GET /hub/api (@172.24.79.160) 49.35ms referer=None
[W 2024-02-20 08:28:42.937 ServerApp] 404 GET /hub/api (@172.24.79.160) 50.52ms referer=None
[W 2024-02-20 08:28:43.976 ServerApp] 404 GET /tree? (@172.24.79.160) 1.45ms referer=None
[W 2024-02-20 08:28:43.977 ServerApp] 404 GET /tree? (@172.24.79.160) 2.12ms referer=None
[W 2024-02-20 08:28:43.978 ServerApp] 404 GET /tree? (@172.24.79.160) 2.83ms referer=None
[W 2024-02-20 08:28:43.979 ServerApp] 404 GET /tree? (@172.24.79.160) 1.05ms referer=None
[W 2024-02-20 08:28:45.357 ServerApp] wrote error: 'Forbidden'
    Traceback (most recent call last):
      File "/home/jaalzate/.local/lib/python3.10/site-packages/tornado/web.py", line 1788, in _execute
        result = method(*self.path_args, **self.path_kwargs)
      File "/home/jaalzate/.local/lib/python3.10/site-packages/tornado/web.py", line 3289, in wrapper
        url = self.get_login_url()
      File "/home/jaalzate/.local/lib/python3.10/site-packages/jupyter_server/base/handlers.py", line 763, in get_login_url
        raise web.HTTPError(403)
    tornado.web.HTTPError: HTTP 403: Forbidden
[W 2024-02-20 08:28:45.400 ServerApp] 403 GET /api/kernelspecs?1708414125238 (@172.24.79.160) 44.55ms referer=None
[W 2024-02-20 08:28:45.401 ServerApp] wrote error: 'Forbidden'
    Traceback (most recent call last):
      File "/home/jaalzate/.local/lib/python3.10/site-packages/tornado/web.py", line 1788, in _execute
        result = method(*self.path_args, **self.path_kwargs)
      File "/home/jaalzate/.local/lib/python3.10/site-packages/tornado/web.py", line 3289, in wrapper
        url = self.get_login_url()
      File "/home/jaalzate/.local/lib/python3.10/site-packages/jupyter_server/base/handlers.py", line 763, in get_login_url
        raise web.HTTPError(403)
    tornado.web.HTTPError: HTTP 403: Forbidden
[W 2024-02-20 08:28:45.401 ServerApp] 403 GET /api/kernels?1708414125251 (@172.24.79.160) 45.32ms referer=None
[W 2024-02-20 08:28:45.402 ServerApp] wrote error: 'Forbidden'
    Traceback (most recent call last):
      File "/home/jaalzate/.local/lib/python3.10/site-packages/tornado/web.py", line 1788, in _execute
        result = method(*self.path_args, **self.path_kwargs)
      File "/home/jaalzate/.local/lib/python3.10/site-packages/tornado/web.py", line 3289, in wrapper
        url = self.get_login_url()
      File "/home/jaalzate/.local/lib/python3.10/site-packages/jupyter_server/base/handlers.py", line 763, in get_login_url
        raise web.HTTPError(403)
    tornado.web.HTTPError: HTTP 403: Forbidden
[W 2024-02-20 08:28:45.402 ServerApp] 403 GET /api/kernels?1708414125254 (@172.24.79.160) 45.69ms referer=None
[W 2024-02-20 08:28:45.403 ServerApp] wrote error: 'Forbidden'
    Traceback (most recent call last):
      File "/home/jaalzate/.local/lib/python3.10/site-packages/tornado/web.py", line 1788, in _execute
        result = method(*self.path_args, **self.path_kwargs)
      File "/home/jaalzate/.local/lib/python3.10/site-packages/tornado/web.py", line 3289, in wrapper
        url = self.get_login_url()
      File "/home/jaalzate/.local/lib/python3.10/site-packages/jupyter_server/base/handlers.py", line 763, in get_login_url
        raise web.HTTPError(403)
    tornado.web.HTTPError: HTTP 403: Forbidden
[W 2024-02-20 08:28:45.403 ServerApp] 403 GET /api/sessions?1708414125256 (@172.24.79.160) 0.89ms referer=None
[W 2024-02-20 08:28:45.438 ServerApp] wrote error: 'Forbidden'
    Traceback (most recent call last):
      File "/home/jaalzate/.local/lib/python3.10/site-packages/tornado/web.py", line 1788, in _execute
        result = method(*self.path_args, **self.path_kwargs)
      File "/home/jaalzate/.local/lib/python3.10/site-packages/tornado/web.py", line 3289, in wrapper
        url = self.get_login_url()
      File "/home/jaalzate/.local/lib/python3.10/site-packages/jupyter_server/base/handlers.py", line 763, in get_login_url
        raise web.HTTPError(403)
    tornado.web.HTTPError: HTTP 403: Forbidden
[W 2024-02-20 08:28:45.439 ServerApp] 403 GET /api/kernelspecs?1708414125363 (@172.24.79.160) 1.32ms referer=None
[W 2024-02-20 08:28:45.441 ServerApp] wrote error: 'Forbidden'
    Traceback (most recent call last):
      File "/home/jaalzate/.local/lib/python3.10/site-packages/tornado/web.py", line 1788, in _execute
        result = method(*self.path_args, **self.path_kwargs)
      File "/home/jaalzate/.local/lib/python3.10/site-packages/tornado/web.py", line 3289, in wrapper
        url = self.get_login_url()
      File "/home/jaalzate/.local/lib/python3.10/site-packages/jupyter_server/base/handlers.py", line 763, in get_login_url
        raise web.HTTPError(403)
    tornado.web.HTTPError: HTTP 403: Forbidden
[W 2024-02-20 08:28:45.442 ServerApp] 403 GET /api/kernels?1708414125365 (@172.24.79.160) 3.04ms referer=None
[W 2024-02-20 08:28:45.442 ServerApp] wrote error: 'Forbidden'
    Traceback (most recent call last):
      File "/home/jaalzate/.local/lib/python3.10/site-packages/tornado/web.py", line 1788, in _execute
        result = method(*self.path_args, **self.path_kwargs)
      File "/home/jaalzate/.local/lib/python3.10/site-packages/tornado/web.py", line 3289, in wrapper
        url = self.get_login_url()
      File "/home/jaalzate/.local/lib/python3.10/site-packages/jupyter_server/base/handlers.py", line 763, in get_login_url
        raise web.HTTPError(403)
    tornado.web.HTTPError: HTTP 403: Forbidden
[W 2024-02-20 08:28:45.443 ServerApp] 403 GET /api/kernelspecs?1708414125366 (@172.24.79.160) 3.80ms referer=None
[W 2024-02-20 08:28:45.444 ServerApp] wrote error: 'Forbidden'
    Traceback (most recent call last):
      File "/home/jaalzate/.local/lib/python3.10/site-packages/tornado/web.py", line 1788, in _execute
        result = method(*self.path_args, **self.path_kwargs)
      File "/home/jaalzate/.local/lib/python3.10/site-packages/tornado/web.py", line 3289, in wrapper
        url = self.get_login_url()
      File "/home/jaalzate/.local/lib/python3.10/site-packages/jupyter_server/base/handlers.py", line 763, in get_login_url
        raise web.HTTPError(403)
    tornado.web.HTTPError: HTTP 403: Forbidden
[W 2024-02-20 08:28:45.444 ServerApp] 403 GET /api/kernels?1708414125367 (@172.24.79.160) 4.56ms referer=None
[W 2024-02-20 08:28:45.445 ServerApp] wrote error: 'Forbidden'
    Traceback (most recent call last):
      File "/home/jaalzate/.local/lib/python3.10/site-packages/tornado/web.py", line 1788, in _execute
        result = method(*self.path_args, **self.path_kwargs)
      File "/home/jaalzate/.local/lib/python3.10/site-packages/tornado/web.py", line 3289, in wrapper
        url = self.get_login_url()
      File "/home/jaalzate/.local/lib/python3.10/site-packages/jupyter_server/base/handlers.py", line 763, in get_login_url
        raise web.HTTPError(403)
    tornado.web.HTTPError: HTTP 403: Forbidden
[W 2024-02-20 08:28:45.445 ServerApp] 403 GET /api/kernels?1708414125369 (@172.24.79.160) 5.38ms referer=None
[W 2024-02-20 08:28:45.446 ServerApp] wrote error: 'Forbidden'
    Traceback (most recent call last):
      File "/home/jaalzate/.local/lib/python3.10/site-packages/tornado/web.py", line 1788, in _execute
        result = method(*self.path_args, **self.path_kwargs)
      File "/home/jaalzate/.local/lib/python3.10/site-packages/tornado/web.py", line 3289, in wrapper
        url = self.get_login_url()
      File "/home/jaalzate/.local/lib/python3.10/site-packages/jupyter_server/base/handlers.py", line 763, in get_login_url
        raise web.HTTPError(403)
    tornado.web.HTTPError: HTTP 403: Forbidden
[W 2024-02-20 08:28:45.446 ServerApp] 403 GET /api/sessions?1708414125371 (@172.24.79.160) 6.17ms referer=None
[W 2024-02-20 08:28:45.447 ServerApp] wrote error: 'Forbidden'
    Traceback (most recent call last):
      File "/home/jaalzate/.local/lib/python3.10/site-packages/tornado/web.py", line 1788, in _execute
        result = method(*self.path_args, **self.path_kwargs)
      File "/home/jaalzate/.local/lib/python3.10/site-packages/tornado/web.py", line 3289, in wrapper
        url = self.get_login_url()
      File "/home/jaalzate/.local/lib/python3.10/site-packages/jupyter_server/base/handlers.py", line 763, in get_login_url
        raise web.HTTPError(403)
    tornado.web.HTTPError: HTTP 403: Forbidden
[W 2024-02-20 08:28:45.448 ServerApp] 403 GET /api/kernels?1708414125372 (@172.24.79.160) 7.03ms referer=None
[W 2024-02-20 08:28:45.449 ServerApp] wrote error: 'Forbidden'
    Traceback (most recent call last):
      File "/home/jaalzate/.local/lib/python3.10/site-packages/tornado/web.py", line 1788, in _execute
        result = method(*self.path_args, **self.path_kwargs)
      File "/home/jaalzate/.local/lib/python3.10/site-packages/tornado/web.py", line 3289, in wrapper
        url = self.get_login_url()
      File "/home/jaalzate/.local/lib/python3.10/site-packages/jupyter_server/base/handlers.py", line 763, in get_login_url
        raise web.HTTPError(403)
    tornado.web.HTTPError: HTTP 403: Forbidden
[W 2024-02-20 08:28:45.450 ServerApp] 403 GET /api/sessions?1708414125374 (@172.24.79.160) 1.23ms referer=None
[I 2024-02-20 08:28:49.850 ServerApp] User d1132c0232f24c72ac20019e6299faa6 logged in.
[I 2024-02-20 08:28:49.852 ServerApp] 302 POST /login? (d1132c0232f24c72ac20019e6299faa6@172.24.79.160) 1485.23ms
[W 2024-02-20 08:28:54.949 ServerApp] 404 GET /hub/api (@172.24.79.160) 2.74ms referer=None
[I 2024-02-20 08:28:55.012 ServerApp] Connecting to kernel 3db022ca-f909-4556-af49-c42e19df514b.
[W 2024-02-20 08:28:55.444 ServerApp] 404 GET /hub/api (@172.24.79.160) 7.89ms referer=None
[W 2024-02-20 08:28:55.445 ServerApp] 404 GET /hub/api (@172.24.79.160) 8.37ms referer=None
[W 2024-02-20 08:28:55.446 ServerApp] 404 GET /hub/api (@172.24.79.160) 8.78ms referer=None
[W 2024-02-20 08:28:55.482 ServerApp] 404 GET /tree? (@172.24.79.160) 5.47ms referer=None
[W 2024-02-20 08:28:55.483 ServerApp] 404 GET /tree? (@172.24.79.160) 1.58ms referer=None
[W 2024-02-20 08:28:55.484 ServerApp] 404 GET /tree? (@172.24.79.160) 2.38ms referer=None
[W 2024-02-20 08:28:55.561 ServerApp] wrote error: 'Forbidden'
    Traceback (most recent call last):
      File "/home/jaalzate/.local/lib/python3.10/site-packages/tornado/web.py", line 1788, in _execute
        result = method(*self.path_args, **self.path_kwargs)
      File "/home/jaalzate/.local/lib/python3.10/site-packages/tornado/web.py", line 3289, in wrapper
        url = self.get_login_url()
      File "/home/jaalzate/.local/lib/python3.10/site-packages/jupyter_server/base/handlers.py", line 763, in get_login_url
        raise web.HTTPError(403)
    tornado.web.HTTPError: HTTP 403: Forbidden
[W 2024-02-20 08:28:55.562 ServerApp] 403 GET /api/kernelspecs?1708414135547 (@172.24.79.160) 1.05ms referer=None
[W 2024-02-20 08:28:55.563 ServerApp] wrote error: 'Forbidden'
    Traceback (most recent call last):
      File "/home/jaalzate/.local/lib/python3.10/site-packages/tornado/web.py", line 1788, in _execute
        result = method(*self.path_args, **self.path_kwargs)
      File "/home/jaalzate/.local/lib/python3.10/site-packages/tornado/web.py", line 3289, in wrapper
        url = self.get_login_url()
      File "/home/jaalzate/.local/lib/python3.10/site-packages/jupyter_server/base/handlers.py", line 763, in get_login_url
        raise web.HTTPError(403)
    tornado.web.HTTPError: HTTP 403: Forbidden
[W 2024-02-20 08:28:55.563 ServerApp] 403 GET /api/kernels?1708414135550 (@172.24.79.160) 1.22ms referer=None
[W 2024-02-20 08:28:55.564 ServerApp] wrote error: 'Forbidden'
    Traceback (most recent call last):
      File "/home/jaalzate/.local/lib/python3.10/site-packages/tornado/web.py", line 1788, in _execute
        result = method(*self.path_args, **self.path_kwargs)
      File "/home/jaalzate/.local/lib/python3.10/site-packages/tornado/web.py", line 3289, in wrapper
        url = self.get_login_url()
      File "/home/jaalzate/.local/lib/python3.10/site-packages/jupyter_server/base/handlers.py", line 763, in get_login_url
        raise web.HTTPError(403)
    tornado.web.HTTPError: HTTP 403: Forbidden
[W 2024-02-20 08:28:55.564 ServerApp] 403 GET /api/kernels?1708414135554 (@172.24.79.160) 1.89ms referer=None
[W 2024-02-20 08:28:55.569 ServerApp] wrote error: 'Forbidden'
    Traceback (most recent call last):
      File "/home/jaalzate/.local/lib/python3.10/site-packages/tornado/web.py", line 1788, in _execute
        result = method(*self.path_args, **self.path_kwargs)
      File "/home/jaalzate/.local/lib/python3.10/site-packages/tornado/web.py", line 3289, in wrapper
        url = self.get_login_url()
      File "/home/jaalzate/.local/lib/python3.10/site-packages/jupyter_server/base/handlers.py", line 763, in get_login_url
        raise web.HTTPError(403)
    tornado.web.HTTPError: HTTP 403: Forbidden
[W 2024-02-20 08:28:55.570 ServerApp] 403 GET /api/sessions?1708414135557 (@172.24.79.160) 1.00ms referer=None
[W 2024-02-20 08:28:55.586 ServerApp] wrote error: 'Forbidden'
    Traceback (most recent call last):
      File "/home/jaalzate/.local/lib/python3.10/site-packages/tornado/web.py", line 1788, in _execute
        result = method(*self.path_args, **self.path_kwargs)
      File "/home/jaalzate/.local/lib/python3.10/site-packages/tornado/web.py", line 3289, in wrapper
        url = self.get_login_url()
      File "/home/jaalzate/.local/lib/python3.10/site-packages/jupyter_server/base/handlers.py", line 763, in get_login_url
        raise web.HTTPError(403)
    tornado.web.HTTPError: HTTP 403: Forbidden
[W 2024-02-20 08:28:55.587 ServerApp] 403 GET /api/sessions?1708414135574 (@172.24.79.160) 2.28ms referer=None
[W 2024-02-20 08:28:55.588 ServerApp] wrote error: 'Forbidden'
    Traceback (most recent call last):
      File "/home/jaalzate/.local/lib/python3.10/site-packages/tornado/web.py", line 1788, in _execute
        result = method(*self.path_args, **self.path_kwargs)
      File "/home/jaalzate/.local/lib/python3.10/site-packages/tornado/web.py", line 3289, in wrapper
        url = self.get_login_url()
      File "/home/jaalzate/.local/lib/python3.10/site-packages/jupyter_server/base/handlers.py", line 763, in get_login_url
        raise web.HTTPError(403)
    tornado.web.HTTPError: HTTP 403: Forbidden
[W 2024-02-20 08:28:55.589 ServerApp] 403 GET /api/kernelspecs?1708414135565 (@172.24.79.160) 3.70ms referer=None
[W 2024-02-20 08:28:55.590 ServerApp] wrote error: 'Forbidden'
    Traceback (most recent call last):
      File "/home/jaalzate/.local/lib/python3.10/site-packages/tornado/web.py", line 1788, in _execute
        result = method(*self.path_args, **self.path_kwargs)
      File "/home/jaalzate/.local/lib/python3.10/site-packages/tornado/web.py", line 3289, in wrapper
        url = self.get_login_url()
      File "/home/jaalzate/.local/lib/python3.10/site-packages/jupyter_server/base/handlers.py", line 763, in get_login_url
        raise web.HTTPError(403)
    tornado.web.HTTPError: HTTP 403: Forbidden
[W 2024-02-20 08:28:55.591 ServerApp] 403 GET /api/kernels?1708414135568 (@172.24.79.160) 2.87ms referer=None
[W 2024-02-20 08:28:55.591 ServerApp] wrote error: 'Forbidden'
    Traceback (most recent call last):
      File "/home/jaalzate/.local/lib/python3.10/site-packages/tornado/web.py", line 1788, in _execute
        result = method(*self.path_args, **self.path_kwargs)
      File "/home/jaalzate/.local/lib/python3.10/site-packages/tornado/web.py", line 3289, in wrapper
        url = self.get_login_url()
      File "/home/jaalzate/.local/lib/python3.10/site-packages/jupyter_server/base/handlers.py", line 763, in get_login_url
        raise web.HTTPError(403)
    tornado.web.HTTPError: HTTP 403: Forbidden
[W 2024-02-20 08:28:55.592 ServerApp] 403 GET /api/kernels?1708414135571 (@172.24.79.160) 1.24ms referer=None
[W 2024-02-20 08:28:55.598 ServerApp] wrote error: 'Forbidden'
    Traceback (most recent call last):
      File "/home/jaalzate/.local/lib/python3.10/site-packages/tornado/web.py", line 1788, in _execute
        result = method(*self.path_args, **self.path_kwargs)
      File "/home/jaalzate/.local/lib/python3.10/site-packages/tornado/web.py", line 3289, in wrapper
        url = self.get_login_url()
      File "/home/jaalzate/.local/lib/python3.10/site-packages/jupyter_server/base/handlers.py", line 763, in get_login_url
        raise web.HTTPError(403)
    tornado.web.HTTPError: HTTP 403: Forbidden
[W 2024-02-20 08:28:55.598 ServerApp] 403 GET /api/kernelspecs?1708414135593 (@172.24.79.160) 1.22ms referer=None
[I 2024-02-20 08:30:43.269 ServerApp] User e93139fcf85d455cbf9987dc751bbd67 logged in.
[I 2024-02-20 08:30:43.270 ServerApp] 302 POST /login? (e93139fcf85d455cbf9987dc751bbd67@172.24.79.160) 60.05ms
[I 2024-02-20 10:53:48.047 ServerApp] Kernel interrupted: 3db022ca-f909-4556-af49-c42e19df514b
[W 2024-02-20 11:56:43.967 ServerApp] 404 GET /hub/api (@172.24.79.160) 7.99ms referer=None
[W 2024-02-20 11:56:43.969 ServerApp] 404 GET /hub/api (@172.24.79.160) 1.59ms referer=None
[W 2024-02-20 11:56:44.003 ServerApp] 404 GET /tree? (@172.24.79.160) 2.07ms referer=None
[W 2024-02-20 11:56:44.005 ServerApp] 404 GET /tree? (@172.24.79.160) 3.02ms referer=None
[W 2024-02-20 11:56:44.076 ServerApp] wrote error: 'Forbidden'
    Traceback (most recent call last):
      File "/home/jaalzate/.local/lib/python3.10/site-packages/tornado/web.py", line 1788, in _execute
        result = method(*self.path_args, **self.path_kwargs)
      File "/home/jaalzate/.local/lib/python3.10/site-packages/tornado/web.py", line 3289, in wrapper
        url = self.get_login_url()
      File "/home/jaalzate/.local/lib/python3.10/site-packages/jupyter_server/base/handlers.py", line 763, in get_login_url
        raise web.HTTPError(403)
    tornado.web.HTTPError: HTTP 403: Forbidden
[W 2024-02-20 11:56:44.079 ServerApp] 403 GET /api/kernels?1708426604068 (@172.24.79.160) 4.56ms referer=None
[W 2024-02-20 11:56:44.079 ServerApp] wrote error: 'Forbidden'
    Traceback (most recent call last):
      File "/home/jaalzate/.local/lib/python3.10/site-packages/tornado/web.py", line 1788, in _execute
        result = method(*self.path_args, **self.path_kwargs)
      File "/home/jaalzate/.local/lib/python3.10/site-packages/tornado/web.py", line 3289, in wrapper
        url = self.get_login_url()
      File "/home/jaalzate/.local/lib/python3.10/site-packages/jupyter_server/base/handlers.py", line 763, in get_login_url
        raise web.HTTPError(403)
    tornado.web.HTTPError: HTTP 403: Forbidden
[W 2024-02-20 11:56:44.080 ServerApp] 403 GET /api/kernels?1708426604065 (@172.24.79.160) 5.35ms referer=None
[W 2024-02-20 11:56:44.081 ServerApp] wrote error: 'Forbidden'
    Traceback (most recent call last):
      File "/home/jaalzate/.local/lib/python3.10/site-packages/tornado/web.py", line 1788, in _execute
        result = method(*self.path_args, **self.path_kwargs)
      File "/home/jaalzate/.local/lib/python3.10/site-packages/tornado/web.py", line 3289, in wrapper
        url = self.get_login_url()
      File "/home/jaalzate/.local/lib/python3.10/site-packages/jupyter_server/base/handlers.py", line 763, in get_login_url
        raise web.HTTPError(403)
    tornado.web.HTTPError: HTTP 403: Forbidden
[W 2024-02-20 11:56:44.082 ServerApp] 403 GET /api/sessions?1708426604072 (@172.24.79.160) 0.96ms referer=None
[W 2024-02-20 11:56:44.082 ServerApp] wrote error: 'Forbidden'
    Traceback (most recent call last):
      File "/home/jaalzate/.local/lib/python3.10/site-packages/tornado/web.py", line 1788, in _execute
        result = method(*self.path_args, **self.path_kwargs)
      File "/home/jaalzate/.local/lib/python3.10/site-packages/tornado/web.py", line 3289, in wrapper
        url = self.get_login_url()
      File "/home/jaalzate/.local/lib/python3.10/site-packages/jupyter_server/base/handlers.py", line 763, in get_login_url
        raise web.HTTPError(403)
    tornado.web.HTTPError: HTTP 403: Forbidden
[W 2024-02-20 11:56:44.083 ServerApp] 403 GET /api/kernelspecs?1708426604061 (@172.24.79.160) 0.88ms referer=None
[I 2024-02-20 11:56:52.291 ServerApp] User de9b69ca90184038b80d81c0bcd563c0 logged in.
[I 2024-02-20 11:56:52.292 ServerApp] 302 POST /login? (de9b69ca90184038b80d81c0bcd563c0@172.24.79.160) 501.35ms
[I 2024-02-20 12:10:26.865 ServerApp] Kernel interrupted: 3db022ca-f909-4556-af49-c42e19df514b
old shape: (24, 308, 308), new_shape: [ 23 205 205], old_spacing: [3.0, 0.3125, 0.3125], new_spacing: [3.089737057685852, 0.46875, 0.46875], fn_data: functools.partial(<function resample_data_or_seg_to_shape at 0x7f642a234e50>, is_seg=False, order=3, order_z=0, force_separate_z=None)
[I 2024-02-20 12:35:19.584 ServerApp] Kernel interrupted: 3db022ca-f909-4556-af49-c42e19df514b
Process SpawnPoolWorker-71:
Process SpawnProcess-76:
Process SpawnProcess-74:
Process SpawnPoolWorker-70:
Traceback (most recent call last):
  File "/opt/sci-soft/software/PyTorch/2.1.2-Miniconda3-CUDA-11.8.0/lib/python3.10/multiprocessing/process.py", line 314, in _bootstrap
    self.run()
  File "/opt/sci-soft/software/PyTorch/2.1.2-Miniconda3-CUDA-11.8.0/lib/python3.10/multiprocessing/process.py", line 108, in run
    self._target(*self._args, **self._kwargs)
  File "/opt/sci-soft/software/PyTorch/2.1.2-Miniconda3-CUDA-11.8.0/lib/python3.10/multiprocessing/pool.py", line 114, in worker
    task = get()
  File "/opt/sci-soft/software/PyTorch/2.1.2-Miniconda3-CUDA-11.8.0/lib/python3.10/multiprocessing/queues.py", line 364, in get
    with self._rlock:
  File "/opt/sci-soft/software/PyTorch/2.1.2-Miniconda3-CUDA-11.8.0/lib/python3.10/multiprocessing/synchronize.py", line 95, in __enter__
    return self._semlock.__enter__()
KeyboardInterrupt
Traceback (most recent call last):
  File "/opt/sci-soft/software/PyTorch/2.1.2-Miniconda3-CUDA-11.8.0/lib/python3.10/multiprocessing/process.py", line 314, in _bootstrap
    self.run()
  File "/opt/sci-soft/software/PyTorch/2.1.2-Miniconda3-CUDA-11.8.0/lib/python3.10/multiprocessing/process.py", line 108, in run
    self._target(*self._args, **self._kwargs)
  File "/clinicfs/userhomes/jaalzate/nnUNet/nnunetv2/inference/data_iterators.py", line 50, in preprocess_fromfiles_save_to_queue
    target_queue.put(item, timeout=0.01)
  File "<string>", line 2, in put
  File "/opt/sci-soft/software/PyTorch/2.1.2-Miniconda3-CUDA-11.8.0/lib/python3.10/multiprocessing/managers.py", line 818, in _callmethod
    kind, result = conn.recv()
  File "/opt/sci-soft/software/PyTorch/2.1.2-Miniconda3-CUDA-11.8.0/lib/python3.10/multiprocessing/connection.py", line 250, in recv
    buf = self._recv_bytes()
  File "/opt/sci-soft/software/PyTorch/2.1.2-Miniconda3-CUDA-11.8.0/lib/python3.10/multiprocessing/connection.py", line 414, in _recv_bytes
    buf = self._recv(4)
  File "/opt/sci-soft/software/PyTorch/2.1.2-Miniconda3-CUDA-11.8.0/lib/python3.10/multiprocessing/connection.py", line 379, in _recv
    chunk = read(handle, remaining)
KeyboardInterrupt
Traceback (most recent call last):
  File "/opt/sci-soft/software/PyTorch/2.1.2-Miniconda3-CUDA-11.8.0/lib/python3.10/multiprocessing/process.py", line 314, in _bootstrap
    self.run()
  File "/opt/sci-soft/software/PyTorch/2.1.2-Miniconda3-CUDA-11.8.0/lib/python3.10/multiprocessing/process.py", line 108, in run
    self._target(*self._args, **self._kwargs)
  File "/clinicfs/userhomes/jaalzate/nnUNet/nnunetv2/inference/data_iterators.py", line 50, in preprocess_fromfiles_save_to_queue
    target_queue.put(item, timeout=0.01)
  File "<string>", line 2, in put
  File "/opt/sci-soft/software/PyTorch/2.1.2-Miniconda3-CUDA-11.8.0/lib/python3.10/multiprocessing/managers.py", line 818, in _callmethod
    kind, result = conn.recv()
  File "/opt/sci-soft/software/PyTorch/2.1.2-Miniconda3-CUDA-11.8.0/lib/python3.10/multiprocessing/connection.py", line 250, in recv
    buf = self._recv_bytes()
  File "/opt/sci-soft/software/PyTorch/2.1.2-Miniconda3-CUDA-11.8.0/lib/python3.10/multiprocessing/connection.py", line 414, in _recv_bytes
    buf = self._recv(4)
  File "/opt/sci-soft/software/PyTorch/2.1.2-Miniconda3-CUDA-11.8.0/lib/python3.10/multiprocessing/connection.py", line 379, in _recv
    chunk = read(handle, remaining)
KeyboardInterrupt
Traceback (most recent call last):
  File "/opt/sci-soft/software/PyTorch/2.1.2-Miniconda3-CUDA-11.8.0/lib/python3.10/multiprocessing/process.py", line 314, in _bootstrap
    self.run()
  File "/opt/sci-soft/software/PyTorch/2.1.2-Miniconda3-CUDA-11.8.0/lib/python3.10/multiprocessing/process.py", line 108, in run
    self._target(*self._args, **self._kwargs)
  File "/opt/sci-soft/software/PyTorch/2.1.2-Miniconda3-CUDA-11.8.0/lib/python3.10/multiprocessing/pool.py", line 114, in worker
    task = get()
  File "/opt/sci-soft/software/PyTorch/2.1.2-Miniconda3-CUDA-11.8.0/lib/python3.10/multiprocessing/queues.py", line 365, in get
    res = self._reader.recv_bytes()
  File "/opt/sci-soft/software/PyTorch/2.1.2-Miniconda3-CUDA-11.8.0/lib/python3.10/multiprocessing/connection.py", line 216, in recv_bytes
    buf = self._recv_bytes(maxlength)
  File "/opt/sci-soft/software/PyTorch/2.1.2-Miniconda3-CUDA-11.8.0/lib/python3.10/multiprocessing/connection.py", line 414, in _recv_bytes
    buf = self._recv(4)
  File "/opt/sci-soft/software/PyTorch/2.1.2-Miniconda3-CUDA-11.8.0/lib/python3.10/multiprocessing/connection.py", line 379, in _recv
    chunk = read(handle, remaining)
KeyboardInterrupt
[I 2024-02-20 12:35:43.782 ServerApp] Kernel interrupted: 3db022ca-f909-4556-af49-c42e19df514b
[I 2024-02-20 12:35:44.919 ServerApp] Kernel interrupted: 3db022ca-f909-4556-af49-c42e19df514b
[I 2024-02-20 12:35:46.881 ServerApp] Kernel interrupted: 3db022ca-f909-4556-af49-c42e19df514b
Process SpawnPoolWorker-78:
Process SpawnPoolWorker-77:
Traceback (most recent call last):
Traceback (most recent call last):
  File "<string>", line 1, in <module>
  File "<string>", line 1, in <module>
  File "/opt/sci-soft/software/PyTorch/2.1.2-Miniconda3-CUDA-11.8.0/lib/python3.10/multiprocessing/spawn.py", line 116, in spawn_main
  File "/opt/sci-soft/software/PyTorch/2.1.2-Miniconda3-CUDA-11.8.0/lib/python3.10/multiprocessing/spawn.py", line 116, in spawn_main
Traceback (most recent call last):
  File "/opt/sci-soft/software/PyTorch/2.1.2-Miniconda3-CUDA-11.8.0/lib/python3.10/multiprocessing/process.py", line 314, in _bootstrap
    self.run()
  File "/opt/sci-soft/software/PyTorch/2.1.2-Miniconda3-CUDA-11.8.0/lib/python3.10/multiprocessing/process.py", line 108, in run
    self._target(*self._args, **self._kwargs)
  File "/opt/sci-soft/software/PyTorch/2.1.2-Miniconda3-CUDA-11.8.0/lib/python3.10/multiprocessing/pool.py", line 114, in worker
    task = get()
  File "/opt/sci-soft/software/PyTorch/2.1.2-Miniconda3-CUDA-11.8.0/lib/python3.10/multiprocessing/queues.py", line 364, in get
    with self._rlock:
  File "/opt/sci-soft/software/PyTorch/2.1.2-Miniconda3-CUDA-11.8.0/lib/python3.10/multiprocessing/synchronize.py", line 95, in __enter__
    return self._semlock.__enter__()
KeyboardInterrupt
    exitcode = _main(fd, parent_sentinel)
  File "/opt/sci-soft/software/PyTorch/2.1.2-Miniconda3-CUDA-11.8.0/lib/python3.10/multiprocessing/spawn.py", line 126, in _main
    exitcode = _main(fd, parent_sentinel)
  File "/opt/sci-soft/software/PyTorch/2.1.2-Miniconda3-CUDA-11.8.0/lib/python3.10/multiprocessing/spawn.py", line 126, in _main
Traceback (most recent call last):
  File "/opt/sci-soft/software/PyTorch/2.1.2-Miniconda3-CUDA-11.8.0/lib/python3.10/multiprocessing/process.py", line 314, in _bootstrap
    self.run()
  File "/opt/sci-soft/software/PyTorch/2.1.2-Miniconda3-CUDA-11.8.0/lib/python3.10/multiprocessing/process.py", line 108, in run
    self._target(*self._args, **self._kwargs)
  File "/opt/sci-soft/software/PyTorch/2.1.2-Miniconda3-CUDA-11.8.0/lib/python3.10/multiprocessing/pool.py", line 114, in worker
    task = get()
  File "/opt/sci-soft/software/PyTorch/2.1.2-Miniconda3-CUDA-11.8.0/lib/python3.10/multiprocessing/queues.py", line 365, in get
    res = self._reader.recv_bytes()
  File "/opt/sci-soft/software/PyTorch/2.1.2-Miniconda3-CUDA-11.8.0/lib/python3.10/multiprocessing/connection.py", line 216, in recv_bytes
    buf = self._recv_bytes(maxlength)
  File "/opt/sci-soft/software/PyTorch/2.1.2-Miniconda3-CUDA-11.8.0/lib/python3.10/multiprocessing/connection.py", line 414, in _recv_bytes
    buf = self._recv(4)
  File "/opt/sci-soft/software/PyTorch/2.1.2-Miniconda3-CUDA-11.8.0/lib/python3.10/multiprocessing/connection.py", line 379, in _recv
    chunk = read(handle, remaining)
KeyboardInterrupt
    self = reduction.pickle.load(from_parent)
  File "/clinicfs/userhomes/jaalzate/nnUNet/nnunetv2/inference/data_iterators.py", line 3, in <module>
    self = reduction.pickle.load(from_parent)
  File "/clinicfs/userhomes/jaalzate/nnUNet/nnunetv2/inference/data_iterators.py", line 3, in <module>
    from torch.multiprocessing import Event, Process, Queue, Manager
  File "/opt/sci-soft/software/PyTorch/2.1.2-Miniconda3-CUDA-11.8.0/lib/python3.10/site-packages/torch/__init__.py", line 1437, in <module>
    from torch.multiprocessing import Event, Process, Queue, Manager
  File "/opt/sci-soft/software/PyTorch/2.1.2-Miniconda3-CUDA-11.8.0/lib/python3.10/site-packages/torch/__init__.py", line 1437, in <module>
    from torch import hub as hub
  File "/opt/sci-soft/software/PyTorch/2.1.2-Miniconda3-CUDA-11.8.0/lib/python3.10/site-packages/torch/hub.py", line 17, in <module>
    from torch import hub as hub
  File "/opt/sci-soft/software/PyTorch/2.1.2-Miniconda3-CUDA-11.8.0/lib/python3.10/site-packages/torch/hub.py", line 17, in <module>
    from urllib.request import urlopen, Request
  File "/opt/sci-soft/software/PyTorch/2.1.2-Miniconda3-CUDA-11.8.0/lib/python3.10/urllib/request.py", line 88, in <module>
    from urllib.request import urlopen, Request
  File "/opt/sci-soft/software/PyTorch/2.1.2-Miniconda3-CUDA-11.8.0/lib/python3.10/urllib/request.py", line 88, in <module>
    import http.client
  File "/opt/sci-soft/software/PyTorch/2.1.2-Miniconda3-CUDA-11.8.0/lib/python3.10/http/__init__.py", line 6, in <module>
    import http.client
  File "/opt/sci-soft/software/PyTorch/2.1.2-Miniconda3-CUDA-11.8.0/lib/python3.10/http/__init__.py", line 6, in <module>
    class HTTPStatus(IntEnum):
  File "/opt/sci-soft/software/PyTorch/2.1.2-Miniconda3-CUDA-11.8.0/lib/python3.10/enum.py", line 311, in __new__
    class HTTPStatus(IntEnum):
  File "/opt/sci-soft/software/PyTorch/2.1.2-Miniconda3-CUDA-11.8.0/lib/python3.10/enum.py", line 302, in __new__
    if canonical_member._value_ == enum_member._value_:
KeyboardInterrupt
    setattr(enum_class, member_name, enum_member)
  File "/opt/sci-soft/software/PyTorch/2.1.2-Miniconda3-CUDA-11.8.0/lib/python3.10/enum.py", line 481, in __setattr__
    super().__setattr__(name, value)
KeyboardInterrupt
[I 2024-02-20 14:31:45.457 ServerApp] Starting buffering for 3db022ca-f909-4556-af49-c42e19df514b:ad0d5d34-bc8c-405a-bd4a-fc4f3a2214bb
[W 2024-02-21 08:42:57.152 ServerApp] 404 GET /hub/api (@172.24.79.160) 38.61ms referer=None
[W 2024-02-21 08:42:57.169 ServerApp] 404 GET /hub/api (@172.24.79.160) 2.97ms referer=None
[W 2024-02-21 08:42:57.171 ServerApp] 404 GET /hub/api (@172.24.79.160) 4.01ms referer=None
[W 2024-02-21 08:42:57.172 ServerApp] 404 GET /hub/api (@172.24.79.160) 4.98ms referer=None
[W 2024-02-21 08:42:57.358 ServerApp] 404 GET /tree? (@172.24.79.160) 1.92ms referer=None
[W 2024-02-21 08:42:57.361 ServerApp] 404 GET /tree? (@172.24.79.160) 1.55ms referer=None
[W 2024-02-21 08:42:57.362 ServerApp] 404 GET /tree? (@172.24.79.160) 1.92ms referer=None
[W 2024-02-21 08:42:57.362 ServerApp] 404 GET /tree? (@172.24.79.160) 2.56ms referer=None
[W 2024-02-21 08:43:03.397 ServerApp] wrote error: 'Forbidden'
    Traceback (most recent call last):
      File "/home/jaalzate/.local/lib/python3.10/site-packages/tornado/web.py", line 1788, in _execute
        result = method(*self.path_args, **self.path_kwargs)
      File "/home/jaalzate/.local/lib/python3.10/site-packages/tornado/web.py", line 3289, in wrapper
        url = self.get_login_url()
      File "/home/jaalzate/.local/lib/python3.10/site-packages/jupyter_server/base/handlers.py", line 763, in get_login_url
        raise web.HTTPError(403)
    tornado.web.HTTPError: HTTP 403: Forbidden
[W 2024-02-21 08:43:03.399 ServerApp] 403 GET /api/kernelspecs?1708501383196 (@172.24.79.160) 2.80ms referer=None
[W 2024-02-21 08:43:03.402 ServerApp] wrote error: 'Forbidden'
    Traceback (most recent call last):
      File "/home/jaalzate/.local/lib/python3.10/site-packages/tornado/web.py", line 1788, in _execute
        result = method(*self.path_args, **self.path_kwargs)
      File "/home/jaalzate/.local/lib/python3.10/site-packages/tornado/web.py", line 3289, in wrapper
        url = self.get_login_url()
      File "/home/jaalzate/.local/lib/python3.10/site-packages/jupyter_server/base/handlers.py", line 763, in get_login_url
        raise web.HTTPError(403)
    tornado.web.HTTPError: HTTP 403: Forbidden
[W 2024-02-21 08:43:03.402 ServerApp] 403 GET /api/kernels?1708501383205 (@172.24.79.160) 2.64ms referer=None
[W 2024-02-21 08:43:03.403 ServerApp] wrote error: 'Forbidden'
    Traceback (most recent call last):
      File "/home/jaalzate/.local/lib/python3.10/site-packages/tornado/web.py", line 1788, in _execute
        result = method(*self.path_args, **self.path_kwargs)
      File "/home/jaalzate/.local/lib/python3.10/site-packages/tornado/web.py", line 3289, in wrapper
        url = self.get_login_url()
      File "/home/jaalzate/.local/lib/python3.10/site-packages/jupyter_server/base/handlers.py", line 763, in get_login_url
        raise web.HTTPError(403)
    tornado.web.HTTPError: HTTP 403: Forbidden
[W 2024-02-21 08:43:03.404 ServerApp] 403 GET /api/kernelspecs?1708501383209 (@172.24.79.160) 3.49ms referer=None
[W 2024-02-21 08:43:03.404 ServerApp] wrote error: 'Forbidden'
    Traceback (most recent call last):
      File "/home/jaalzate/.local/lib/python3.10/site-packages/tornado/web.py", line 1788, in _execute
        result = method(*self.path_args, **self.path_kwargs)
      File "/home/jaalzate/.local/lib/python3.10/site-packages/tornado/web.py", line 3289, in wrapper
        url = self.get_login_url()
      File "/home/jaalzate/.local/lib/python3.10/site-packages/jupyter_server/base/handlers.py", line 763, in get_login_url
        raise web.HTTPError(403)
    tornado.web.HTTPError: HTTP 403: Forbidden
[W 2024-02-21 08:43:03.405 ServerApp] 403 GET /api/kernels?1708501383213 (@172.24.79.160) 4.35ms referer=None
[W 2024-02-21 08:43:03.407 ServerApp] wrote error: 'Forbidden'
    Traceback (most recent call last):
      File "/home/jaalzate/.local/lib/python3.10/site-packages/tornado/web.py", line 1788, in _execute
        result = method(*self.path_args, **self.path_kwargs)
      File "/home/jaalzate/.local/lib/python3.10/site-packages/tornado/web.py", line 3289, in wrapper
        url = self.get_login_url()
      File "/home/jaalzate/.local/lib/python3.10/site-packages/jupyter_server/base/handlers.py", line 763, in get_login_url
        raise web.HTTPError(403)
    tornado.web.HTTPError: HTTP 403: Forbidden
[W 2024-02-21 08:43:03.408 ServerApp] 403 GET /api/kernelspecs?1708501383217 (@172.24.79.160) 2.54ms referer=None
[W 2024-02-21 08:43:03.408 ServerApp] wrote error: 'Forbidden'
    Traceback (most recent call last):
      File "/home/jaalzate/.local/lib/python3.10/site-packages/tornado/web.py", line 1788, in _execute
        result = method(*self.path_args, **self.path_kwargs)
      File "/home/jaalzate/.local/lib/python3.10/site-packages/tornado/web.py", line 3289, in wrapper
        url = self.get_login_url()
      File "/home/jaalzate/.local/lib/python3.10/site-packages/jupyter_server/base/handlers.py", line 763, in get_login_url
        raise web.HTTPError(403)
    tornado.web.HTTPError: HTTP 403: Forbidden
[W 2024-02-21 08:43:03.409 ServerApp] 403 GET /api/kernels?1708501383220 (@172.24.79.160) 3.35ms referer=None
[W 2024-02-21 08:43:03.409 ServerApp] wrote error: 'Forbidden'
    Traceback (most recent call last):
      File "/home/jaalzate/.local/lib/python3.10/site-packages/tornado/web.py", line 1788, in _execute
        result = method(*self.path_args, **self.path_kwargs)
      File "/home/jaalzate/.local/lib/python3.10/site-packages/tornado/web.py", line 3289, in wrapper
        url = self.get_login_url()
      File "/home/jaalzate/.local/lib/python3.10/site-packages/jupyter_server/base/handlers.py", line 763, in get_login_url
        raise web.HTTPError(403)
    tornado.web.HTTPError: HTTP 403: Forbidden
[W 2024-02-21 08:43:03.410 ServerApp] 403 GET /api/kernelspecs?1708501383223 (@172.24.79.160) 4.23ms referer=None
[W 2024-02-21 08:43:03.410 ServerApp] wrote error: 'Forbidden'
    Traceback (most recent call last):
      File "/home/jaalzate/.local/lib/python3.10/site-packages/tornado/web.py", line 1788, in _execute
        result = method(*self.path_args, **self.path_kwargs)
      File "/home/jaalzate/.local/lib/python3.10/site-packages/tornado/web.py", line 3289, in wrapper
        url = self.get_login_url()
      File "/home/jaalzate/.local/lib/python3.10/site-packages/jupyter_server/base/handlers.py", line 763, in get_login_url
        raise web.HTTPError(403)
    tornado.web.HTTPError: HTTP 403: Forbidden
[W 2024-02-21 08:43:03.411 ServerApp] 403 GET /api/kernels?1708501383226 (@172.24.79.160) 4.61ms referer=None
[W 2024-02-21 08:43:03.414 ServerApp] wrote error: 'Forbidden'
    Traceback (most recent call last):
      File "/home/jaalzate/.local/lib/python3.10/site-packages/tornado/web.py", line 1788, in _execute
        result = method(*self.path_args, **self.path_kwargs)
      File "/home/jaalzate/.local/lib/python3.10/site-packages/tornado/web.py", line 3289, in wrapper
        url = self.get_login_url()
      File "/home/jaalzate/.local/lib/python3.10/site-packages/jupyter_server/base/handlers.py", line 763, in get_login_url
        raise web.HTTPError(403)
    tornado.web.HTTPError: HTTP 403: Forbidden
[W 2024-02-21 08:43:03.414 ServerApp] 403 GET /api/kernelspecs?1708501383229 (@172.24.79.160) 3.06ms referer=None
[W 2024-02-21 08:43:03.414 ServerApp] wrote error: 'Forbidden'
    Traceback (most recent call last):
      File "/home/jaalzate/.local/lib/python3.10/site-packages/tornado/web.py", line 1788, in _execute
        result = method(*self.path_args, **self.path_kwargs)
      File "/home/jaalzate/.local/lib/python3.10/site-packages/tornado/web.py", line 3289, in wrapper
        url = self.get_login_url()
      File "/home/jaalzate/.local/lib/python3.10/site-packages/jupyter_server/base/handlers.py", line 763, in get_login_url
        raise web.HTTPError(403)
    tornado.web.HTTPError: HTTP 403: Forbidden
[W 2024-02-21 08:43:03.415 ServerApp] 403 GET /api/kernels?1708501383233 (@172.24.79.160) 3.55ms referer=None
[W 2024-02-21 08:43:03.415 ServerApp] wrote error: 'Forbidden'
    Traceback (most recent call last):
      File "/home/jaalzate/.local/lib/python3.10/site-packages/tornado/web.py", line 1788, in _execute
        result = method(*self.path_args, **self.path_kwargs)
      File "/home/jaalzate/.local/lib/python3.10/site-packages/tornado/web.py", line 3289, in wrapper
        url = self.get_login_url()
      File "/home/jaalzate/.local/lib/python3.10/site-packages/jupyter_server/base/handlers.py", line 763, in get_login_url
        raise web.HTTPError(403)
    tornado.web.HTTPError: HTTP 403: Forbidden
[W 2024-02-21 08:43:03.415 ServerApp] 403 GET /api/kernels?1708501383295 (@172.24.79.160) 4.07ms referer=None
[W 2024-02-21 08:43:03.416 ServerApp] wrote error: 'Forbidden'
    Traceback (most recent call last):
      File "/home/jaalzate/.local/lib/python3.10/site-packages/tornado/web.py", line 1788, in _execute
        result = method(*self.path_args, **self.path_kwargs)
      File "/home/jaalzate/.local/lib/python3.10/site-packages/tornado/web.py", line 3289, in wrapper
        url = self.get_login_url()
      File "/home/jaalzate/.local/lib/python3.10/site-packages/jupyter_server/base/handlers.py", line 763, in get_login_url
        raise web.HTTPError(403)
    tornado.web.HTTPError: HTTP 403: Forbidden
[W 2024-02-21 08:43:03.416 ServerApp] 403 GET /api/sessions?1708501383308 (@172.24.79.160) 4.59ms referer=None
[W 2024-02-21 08:43:03.416 ServerApp] wrote error: 'Forbidden'
    Traceback (most recent call last):
      File "/home/jaalzate/.local/lib/python3.10/site-packages/tornado/web.py", line 1788, in _execute
        result = method(*self.path_args, **self.path_kwargs)
      File "/home/jaalzate/.local/lib/python3.10/site-packages/tornado/web.py", line 3289, in wrapper
        url = self.get_login_url()
      File "/home/jaalzate/.local/lib/python3.10/site-packages/jupyter_server/base/handlers.py", line 763, in get_login_url
        raise web.HTTPError(403)
    tornado.web.HTTPError: HTTP 403: Forbidden
[W 2024-02-21 08:43:03.417 ServerApp] 403 GET /api/kernels?1708501383315 (@172.24.79.160) 5.12ms referer=None
[W 2024-02-21 08:43:03.417 ServerApp] wrote error: 'Forbidden'
    Traceback (most recent call last):
      File "/home/jaalzate/.local/lib/python3.10/site-packages/tornado/web.py", line 1788, in _execute
        result = method(*self.path_args, **self.path_kwargs)
      File "/home/jaalzate/.local/lib/python3.10/site-packages/tornado/web.py", line 3289, in wrapper
        url = self.get_login_url()
      File "/home/jaalzate/.local/lib/python3.10/site-packages/jupyter_server/base/handlers.py", line 763, in get_login_url
        raise web.HTTPError(403)
    tornado.web.HTTPError: HTTP 403: Forbidden
[W 2024-02-21 08:43:03.418 ServerApp] 403 GET /api/sessions?1708501383321 (@172.24.79.160) 5.66ms referer=None
[W 2024-02-21 08:43:03.418 ServerApp] wrote error: 'Forbidden'
    Traceback (most recent call last):
      File "/home/jaalzate/.local/lib/python3.10/site-packages/tornado/web.py", line 1788, in _execute
        result = method(*self.path_args, **self.path_kwargs)
      File "/home/jaalzate/.local/lib/python3.10/site-packages/tornado/web.py", line 3289, in wrapper
        url = self.get_login_url()
      File "/home/jaalzate/.local/lib/python3.10/site-packages/jupyter_server/base/handlers.py", line 763, in get_login_url
        raise web.HTTPError(403)
    tornado.web.HTTPError: HTTP 403: Forbidden
[W 2024-02-21 08:43:03.418 ServerApp] 403 GET /api/kernels?1708501383326 (@172.24.79.160) 6.21ms referer=None
[W 2024-02-21 08:43:03.419 ServerApp] wrote error: 'Forbidden'
    Traceback (most recent call last):
      File "/home/jaalzate/.local/lib/python3.10/site-packages/tornado/web.py", line 1788, in _execute
        result = method(*self.path_args, **self.path_kwargs)
      File "/home/jaalzate/.local/lib/python3.10/site-packages/tornado/web.py", line 3289, in wrapper
        url = self.get_login_url()
      File "/home/jaalzate/.local/lib/python3.10/site-packages/jupyter_server/base/handlers.py", line 763, in get_login_url
        raise web.HTTPError(403)
    tornado.web.HTTPError: HTTP 403: Forbidden
[W 2024-02-21 08:43:03.419 ServerApp] 403 GET /api/sessions?1708501383331 (@172.24.79.160) 6.76ms referer=None
[W 2024-02-21 08:43:03.419 ServerApp] wrote error: 'Forbidden'
    Traceback (most recent call last):
      File "/home/jaalzate/.local/lib/python3.10/site-packages/tornado/web.py", line 1788, in _execute
        result = method(*self.path_args, **self.path_kwargs)
      File "/home/jaalzate/.local/lib/python3.10/site-packages/tornado/web.py", line 3289, in wrapper
        url = self.get_login_url()
      File "/home/jaalzate/.local/lib/python3.10/site-packages/jupyter_server/base/handlers.py", line 763, in get_login_url
        raise web.HTTPError(403)
    tornado.web.HTTPError: HTTP 403: Forbidden
[W 2024-02-21 08:43:03.420 ServerApp] 403 GET /api/kernels?1708501383336 (@172.24.79.160) 7.30ms referer=None
[W 2024-02-21 08:43:03.420 ServerApp] wrote error: 'Forbidden'
    Traceback (most recent call last):
      File "/home/jaalzate/.local/lib/python3.10/site-packages/tornado/web.py", line 1788, in _execute
        result = method(*self.path_args, **self.path_kwargs)
      File "/home/jaalzate/.local/lib/python3.10/site-packages/tornado/web.py", line 3289, in wrapper
        url = self.get_login_url()
      File "/home/jaalzate/.local/lib/python3.10/site-packages/jupyter_server/base/handlers.py", line 763, in get_login_url
        raise web.HTTPError(403)
    tornado.web.HTTPError: HTTP 403: Forbidden
[W 2024-02-21 08:43:03.421 ServerApp] 403 GET /api/sessions?1708501383341 (@172.24.79.160) 7.72ms referer=None
[W 2024-02-21 08:43:03.421 ServerApp] wrote error: 'Forbidden'
    Traceback (most recent call last):
      File "/home/jaalzate/.local/lib/python3.10/site-packages/tornado/web.py", line 1788, in _execute
        result = method(*self.path_args, **self.path_kwargs)
      File "/home/jaalzate/.local/lib/python3.10/site-packages/tornado/web.py", line 3289, in wrapper
        url = self.get_login_url()
      File "/home/jaalzate/.local/lib/python3.10/site-packages/jupyter_server/base/handlers.py", line 763, in get_login_url
        raise web.HTTPError(403)
    tornado.web.HTTPError: HTTP 403: Forbidden
[W 2024-02-21 08:43:03.421 ServerApp] 403 GET /api/kernels?1708501383346 (@172.24.79.160) 8.24ms referer=None
[W 2024-02-21 08:43:03.422 ServerApp] wrote error: 'Forbidden'
    Traceback (most recent call last):
      File "/home/jaalzate/.local/lib/python3.10/site-packages/tornado/web.py", line 1788, in _execute
        result = method(*self.path_args, **self.path_kwargs)
      File "/home/jaalzate/.local/lib/python3.10/site-packages/tornado/web.py", line 3289, in wrapper
        url = self.get_login_url()
      File "/home/jaalzate/.local/lib/python3.10/site-packages/jupyter_server/base/handlers.py", line 763, in get_login_url
        raise web.HTTPError(403)
    tornado.web.HTTPError: HTTP 403: Forbidden
[W 2024-02-21 08:43:03.422 ServerApp] 403 GET /api/sessions?1708501383351 (@172.24.79.160) 8.77ms referer=None
[W 2024-02-21 08:43:03.462 ServerApp] 404 GET /hub/api (@172.24.79.160) 2.48ms referer=None
[W 2024-02-21 08:43:03.464 ServerApp] wrote error: 'Forbidden'
    Traceback (most recent call last):
      File "/home/jaalzate/.local/lib/python3.10/site-packages/tornado/web.py", line 1788, in _execute
        result = method(*self.path_args, **self.path_kwargs)
      File "/home/jaalzate/.local/lib/python3.10/site-packages/tornado/web.py", line 3289, in wrapper
        url = self.get_login_url()
      File "/home/jaalzate/.local/lib/python3.10/site-packages/jupyter_server/base/handlers.py", line 763, in get_login_url
        raise web.HTTPError(403)
    tornado.web.HTTPError: HTTP 403: Forbidden
[W 2024-02-21 08:43:03.465 ServerApp] 403 GET /api/kernelspecs?1708501383406 (@172.24.79.160) 1.89ms referer=None
[W 2024-02-21 08:43:03.466 ServerApp] wrote error: 'Forbidden'
    Traceback (most recent call last):
      File "/home/jaalzate/.local/lib/python3.10/site-packages/tornado/web.py", line 1788, in _execute
        result = method(*self.path_args, **self.path_kwargs)
      File "/home/jaalzate/.local/lib/python3.10/site-packages/tornado/web.py", line 3289, in wrapper
        url = self.get_login_url()
      File "/home/jaalzate/.local/lib/python3.10/site-packages/jupyter_server/base/handlers.py", line 763, in get_login_url
        raise web.HTTPError(403)
    tornado.web.HTTPError: HTTP 403: Forbidden
[W 2024-02-21 08:43:03.467 ServerApp] 403 GET /api/kernelspecs?1708501383419 (@172.24.79.160) 2.31ms referer=None
[W 2024-02-21 08:43:03.468 ServerApp] wrote error: 'Forbidden'
    Traceback (most recent call last):
      File "/home/jaalzate/.local/lib/python3.10/site-packages/tornado/web.py", line 1788, in _execute
        result = method(*self.path_args, **self.path_kwargs)
      File "/home/jaalzate/.local/lib/python3.10/site-packages/tornado/web.py", line 3289, in wrapper
        url = self.get_login_url()
      File "/home/jaalzate/.local/lib/python3.10/site-packages/jupyter_server/base/handlers.py", line 763, in get_login_url
        raise web.HTTPError(403)
    tornado.web.HTTPError: HTTP 403: Forbidden
[W 2024-02-21 08:43:03.469 ServerApp] 403 GET /api/kernelspecs?1708501383424 (@172.24.79.160) 3.38ms referer=None
[W 2024-02-21 08:43:03.471 ServerApp] 404 GET /hub/api (@172.24.79.160) 1.40ms referer=None
[W 2024-02-21 08:43:03.477 ServerApp] 404 GET /tree? (@172.24.79.160) 0.94ms referer=None
[W 2024-02-21 08:43:03.486 ServerApp] 404 GET /tree? (@172.24.79.160) 1.60ms referer=None
[W 2024-02-21 08:43:04.919 ServerApp] 404 GET /hub/api (@172.24.79.160) 2.44ms referer=None
[W 2024-02-21 08:43:04.924 ServerApp] wrote error: 'Forbidden'
    Traceback (most recent call last):
      File "/home/jaalzate/.local/lib/python3.10/site-packages/tornado/web.py", line 1788, in _execute
        result = method(*self.path_args, **self.path_kwargs)
      File "/home/jaalzate/.local/lib/python3.10/site-packages/tornado/web.py", line 3289, in wrapper
        url = self.get_login_url()
      File "/home/jaalzate/.local/lib/python3.10/site-packages/jupyter_server/base/handlers.py", line 763, in get_login_url
        raise web.HTTPError(403)
    tornado.web.HTTPError: HTTP 403: Forbidden
[W 2024-02-21 08:43:04.925 ServerApp] 403 GET /api/kernels?1708501384917 (@172.24.79.160) 1.29ms referer=None
[W 2024-02-21 08:43:04.927 ServerApp] wrote error: 'Forbidden'
    Traceback (most recent call last):
      File "/home/jaalzate/.local/lib/python3.10/site-packages/tornado/web.py", line 1788, in _execute
        result = method(*self.path_args, **self.path_kwargs)
      File "/home/jaalzate/.local/lib/python3.10/site-packages/tornado/web.py", line 3289, in wrapper
        url = self.get_login_url()
      File "/home/jaalzate/.local/lib/python3.10/site-packages/jupyter_server/base/handlers.py", line 763, in get_login_url
        raise web.HTTPError(403)
    tornado.web.HTTPError: HTTP 403: Forbidden
[W 2024-02-21 08:43:04.927 ServerApp] 403 GET /api/kernelspecs?1708501384913 (@172.24.79.160) 1.82ms referer=None
[W 2024-02-21 08:43:04.928 ServerApp] wrote error: 'Forbidden'
    Traceback (most recent call last):
      File "/home/jaalzate/.local/lib/python3.10/site-packages/tornado/web.py", line 1788, in _execute
        result = method(*self.path_args, **self.path_kwargs)
      File "/home/jaalzate/.local/lib/python3.10/site-packages/tornado/web.py", line 3289, in wrapper
        url = self.get_login_url()
      File "/home/jaalzate/.local/lib/python3.10/site-packages/jupyter_server/base/handlers.py", line 763, in get_login_url
        raise web.HTTPError(403)
    tornado.web.HTTPError: HTTP 403: Forbidden
[W 2024-02-21 08:43:04.928 ServerApp] 403 GET /api/kernels?1708501384915 (@172.24.79.160) 2.56ms referer=None
[W 2024-02-21 08:43:04.929 ServerApp] wrote error: 'Forbidden'
    Traceback (most recent call last):
      File "/home/jaalzate/.local/lib/python3.10/site-packages/tornado/web.py", line 1788, in _execute
        result = method(*self.path_args, **self.path_kwargs)
      File "/home/jaalzate/.local/lib/python3.10/site-packages/tornado/web.py", line 3289, in wrapper
        url = self.get_login_url()
      File "/home/jaalzate/.local/lib/python3.10/site-packages/jupyter_server/base/handlers.py", line 763, in get_login_url
        raise web.HTTPError(403)
    tornado.web.HTTPError: HTTP 403: Forbidden
[W 2024-02-21 08:43:04.930 ServerApp] 403 GET /api/sessions?1708501384919 (@172.24.79.160) 3.36ms referer=None
[W 2024-02-21 08:43:04.945 ServerApp] wrote error: 'Forbidden'
    Traceback (most recent call last):
      File "/home/jaalzate/.local/lib/python3.10/site-packages/tornado/web.py", line 1788, in _execute
        result = method(*self.path_args, **self.path_kwargs)
      File "/home/jaalzate/.local/lib/python3.10/site-packages/tornado/web.py", line 3289, in wrapper
        url = self.get_login_url()
      File "/home/jaalzate/.local/lib/python3.10/site-packages/jupyter_server/base/handlers.py", line 763, in get_login_url
        raise web.HTTPError(403)
    tornado.web.HTTPError: HTTP 403: Forbidden
[W 2024-02-21 08:43:04.946 ServerApp] 403 GET /api/kernelspecs?1708501384926 (@172.24.79.160) 1.59ms referer=None
[W 2024-02-21 08:43:04.948 ServerApp] wrote error: 'Forbidden'
    Traceback (most recent call last):
      File "/home/jaalzate/.local/lib/python3.10/site-packages/tornado/web.py", line 1788, in _execute
        result = method(*self.path_args, **self.path_kwargs)
      File "/home/jaalzate/.local/lib/python3.10/site-packages/tornado/web.py", line 3289, in wrapper
        url = self.get_login_url()
      File "/home/jaalzate/.local/lib/python3.10/site-packages/jupyter_server/base/handlers.py", line 763, in get_login_url
        raise web.HTTPError(403)
    tornado.web.HTTPError: HTTP 403: Forbidden
[W 2024-02-21 08:43:04.949 ServerApp] 403 GET /api/kernels?1708501384928 (@172.24.79.160) 2.06ms referer=None
[W 2024-02-21 08:43:04.949 ServerApp] wrote error: 'Forbidden'
    Traceback (most recent call last):
      File "/home/jaalzate/.local/lib/python3.10/site-packages/tornado/web.py", line 1788, in _execute
        result = method(*self.path_args, **self.path_kwargs)
      File "/home/jaalzate/.local/lib/python3.10/site-packages/tornado/web.py", line 3289, in wrapper
        url = self.get_login_url()
      File "/home/jaalzate/.local/lib/python3.10/site-packages/jupyter_server/base/handlers.py", line 763, in get_login_url
        raise web.HTTPError(403)
    tornado.web.HTTPError: HTTP 403: Forbidden
[W 2024-02-21 08:43:04.950 ServerApp] 403 GET /api/kernels?1708501384930 (@172.24.79.160) 2.94ms referer=None
[W 2024-02-21 08:43:04.951 ServerApp] wrote error: 'Forbidden'
    Traceback (most recent call last):
      File "/home/jaalzate/.local/lib/python3.10/site-packages/tornado/web.py", line 1788, in _execute
        result = method(*self.path_args, **self.path_kwargs)
      File "/home/jaalzate/.local/lib/python3.10/site-packages/tornado/web.py", line 3289, in wrapper
        url = self.get_login_url()
      File "/home/jaalzate/.local/lib/python3.10/site-packages/jupyter_server/base/handlers.py", line 763, in get_login_url
        raise web.HTTPError(403)
    tornado.web.HTTPError: HTTP 403: Forbidden
[W 2024-02-21 08:43:04.951 ServerApp] 403 GET /api/sessions?1708501384932 (@172.24.79.160) 1.09ms referer=None
[I 2024-02-21 08:57:50.758 ServerApp] User 4d01f405289e45949594420037653940 logged in.
[I 2024-02-21 08:57:50.759 ServerApp] 302 POST /login? (4d01f405289e45949594420037653940@172.24.79.160) 193.64ms
[I 2024-02-21 08:57:50.915 ServerApp] Connecting to kernel 3db022ca-f909-4556-af49-c42e19df514b.
[W 2024-02-21 08:57:51.279 ServerApp] 404 GET /hub/api (@172.24.79.160) 6.92ms referer=None
[W 2024-02-21 08:57:51.280 ServerApp] 404 GET /hub/api (@172.24.79.160) 7.88ms referer=None
[W 2024-02-21 08:57:51.281 ServerApp] 404 GET /hub/api (@172.24.79.160) 8.56ms referer=None
[W 2024-02-21 08:57:51.320 ServerApp] 404 GET /tree? (@172.24.79.160) 7.35ms referer=None
[W 2024-02-21 08:57:51.321 ServerApp] 404 GET /tree? (@172.24.79.160) 7.87ms referer=None
[W 2024-02-21 08:57:51.321 ServerApp] 404 GET /tree? (@172.24.79.160) 8.32ms referer=None
[W 2024-02-21 08:57:51.360 ServerApp] wrote error: 'Forbidden'
    Traceback (most recent call last):
      File "/home/jaalzate/.local/lib/python3.10/site-packages/tornado/web.py", line 1788, in _execute
        result = method(*self.path_args, **self.path_kwargs)
      File "/home/jaalzate/.local/lib/python3.10/site-packages/tornado/web.py", line 3289, in wrapper
        url = self.get_login_url()
      File "/home/jaalzate/.local/lib/python3.10/site-packages/jupyter_server/base/handlers.py", line 763, in get_login_url
        raise web.HTTPError(403)
    tornado.web.HTTPError: HTTP 403: Forbidden
[W 2024-02-21 08:57:51.360 ServerApp] 403 GET /api/kernelspecs?1708502271343 (@172.24.79.160) 3.25ms referer=None
[W 2024-02-21 08:57:51.361 ServerApp] wrote error: 'Forbidden'
    Traceback (most recent call last):
      File "/home/jaalzate/.local/lib/python3.10/site-packages/tornado/web.py", line 1788, in _execute
        result = method(*self.path_args, **self.path_kwargs)
      File "/home/jaalzate/.local/lib/python3.10/site-packages/tornado/web.py", line 3289, in wrapper
        url = self.get_login_url()
      File "/home/jaalzate/.local/lib/python3.10/site-packages/jupyter_server/base/handlers.py", line 763, in get_login_url
        raise web.HTTPError(403)
    tornado.web.HTTPError: HTTP 403: Forbidden
[W 2024-02-21 08:57:51.361 ServerApp] 403 GET /api/kernels?1708502271346 (@172.24.79.160) 3.11ms referer=None
[W 2024-02-21 08:57:51.361 ServerApp] wrote error: 'Forbidden'
    Traceback (most recent call last):
      File "/home/jaalzate/.local/lib/python3.10/site-packages/tornado/web.py", line 1788, in _execute
        result = method(*self.path_args, **self.path_kwargs)
      File "/home/jaalzate/.local/lib/python3.10/site-packages/tornado/web.py", line 3289, in wrapper
        url = self.get_login_url()
      File "/home/jaalzate/.local/lib/python3.10/site-packages/jupyter_server/base/handlers.py", line 763, in get_login_url
        raise web.HTTPError(403)
    tornado.web.HTTPError: HTTP 403: Forbidden
[W 2024-02-21 08:57:51.362 ServerApp] 403 GET /api/kernels?1708502271352 (@172.24.79.160) 3.07ms referer=None
[W 2024-02-21 08:57:51.362 ServerApp] wrote error: 'Forbidden'
    Traceback (most recent call last):
      File "/home/jaalzate/.local/lib/python3.10/site-packages/tornado/web.py", line 1788, in _execute
        result = method(*self.path_args, **self.path_kwargs)
      File "/home/jaalzate/.local/lib/python3.10/site-packages/tornado/web.py", line 3289, in wrapper
        url = self.get_login_url()
      File "/home/jaalzate/.local/lib/python3.10/site-packages/jupyter_server/base/handlers.py", line 763, in get_login_url
        raise web.HTTPError(403)
    tornado.web.HTTPError: HTTP 403: Forbidden
[W 2024-02-21 08:57:51.363 ServerApp] 403 GET /api/sessions?1708502271354 (@172.24.79.160) 3.03ms referer=None
[W 2024-02-21 08:57:51.379 ServerApp] wrote error: 'Forbidden'
    Traceback (most recent call last):
      File "/home/jaalzate/.local/lib/python3.10/site-packages/tornado/web.py", line 1788, in _execute
        result = method(*self.path_args, **self.path_kwargs)
      File "/home/jaalzate/.local/lib/python3.10/site-packages/tornado/web.py", line 3289, in wrapper
        url = self.get_login_url()
      File "/home/jaalzate/.local/lib/python3.10/site-packages/jupyter_server/base/handlers.py", line 763, in get_login_url
        raise web.HTTPError(403)
    tornado.web.HTTPError: HTTP 403: Forbidden
[W 2024-02-21 08:57:51.380 ServerApp] 403 GET /api/sessions?1708502271371 (@172.24.79.160) 1.97ms referer=None
[W 2024-02-21 08:57:51.380 ServerApp] wrote error: 'Forbidden'
    Traceback (most recent call last):
      File "/home/jaalzate/.local/lib/python3.10/site-packages/tornado/web.py", line 1788, in _execute
        result = method(*self.path_args, **self.path_kwargs)
      File "/home/jaalzate/.local/lib/python3.10/site-packages/tornado/web.py", line 3289, in wrapper
        url = self.get_login_url()
      File "/home/jaalzate/.local/lib/python3.10/site-packages/jupyter_server/base/handlers.py", line 763, in get_login_url
        raise web.HTTPError(403)
    tornado.web.HTTPError: HTTP 403: Forbidden
[W 2024-02-21 08:57:51.381 ServerApp] 403 GET /api/kernelspecs?1708502271360 (@172.24.79.160) 2.74ms referer=None
[W 2024-02-21 08:57:51.381 ServerApp] wrote error: 'Forbidden'
    Traceback (most recent call last):
      File "/home/jaalzate/.local/lib/python3.10/site-packages/tornado/web.py", line 1788, in _execute
        result = method(*self.path_args, **self.path_kwargs)
      File "/home/jaalzate/.local/lib/python3.10/site-packages/tornado/web.py", line 3289, in wrapper
        url = self.get_login_url()
      File "/home/jaalzate/.local/lib/python3.10/site-packages/jupyter_server/base/handlers.py", line 763, in get_login_url
        raise web.HTTPError(403)
    tornado.web.HTTPError: HTTP 403: Forbidden
[W 2024-02-21 08:57:51.382 ServerApp] 403 GET /api/kernels?1708502271363 (@172.24.79.160) 3.60ms referer=None
[W 2024-02-21 08:57:51.383 ServerApp] wrote error: 'Forbidden'
    Traceback (most recent call last):
      File "/home/jaalzate/.local/lib/python3.10/site-packages/tornado/web.py", line 1788, in _execute
        result = method(*self.path_args, **self.path_kwargs)
      File "/home/jaalzate/.local/lib/python3.10/site-packages/tornado/web.py", line 3289, in wrapper
        url = self.get_login_url()
      File "/home/jaalzate/.local/lib/python3.10/site-packages/jupyter_server/base/handlers.py", line 763, in get_login_url
        raise web.HTTPError(403)
    tornado.web.HTTPError: HTTP 403: Forbidden
[W 2024-02-21 08:57:51.384 ServerApp] 403 GET /api/kernels?1708502271366 (@172.24.79.160) 1.40ms referer=None
[W 2024-02-21 08:57:51.390 ServerApp] wrote error: 'Forbidden'
    Traceback (most recent call last):
      File "/home/jaalzate/.local/lib/python3.10/site-packages/tornado/web.py", line 1788, in _execute
        result = method(*self.path_args, **self.path_kwargs)
      File "/home/jaalzate/.local/lib/python3.10/site-packages/tornado/web.py", line 3289, in wrapper
        url = self.get_login_url()
      File "/home/jaalzate/.local/lib/python3.10/site-packages/jupyter_server/base/handlers.py", line 763, in get_login_url
        raise web.HTTPError(403)
    tornado.web.HTTPError: HTTP 403: Forbidden
[W 2024-02-21 08:57:51.391 ServerApp] 403 GET /api/kernelspecs?1708502271384 (@172.24.79.160) 1.16ms referer=None
[I 2024-02-21 08:58:10.143 ServerApp] User 7efc148abbdb4af1b8c212e0379fe98c logged in.
[I 2024-02-21 08:58:10.144 ServerApp] 302 POST /login? (7efc148abbdb4af1b8c212e0379fe98c@172.24.79.160) 48.77ms
[I 2024-02-21 10:03:55.840 ServerApp] Starting buffering for 3db022ca-f909-4556-af49-c42e19df514b:2b186197-4e47-4ff0-917d-0262b15d80d5
[W 2024-02-21 10:03:57.984 ServerApp] 404 GET /hub/api (@172.24.79.160) 6.55ms referer=None
[W 2024-02-21 10:03:57.985 ServerApp] 404 GET /hub/api (@172.24.79.160) 7.26ms referer=None
[W 2024-02-21 10:03:58.004 ServerApp] 404 GET /tree? (@172.24.79.160) 1.13ms referer=None
[W 2024-02-21 10:03:58.005 ServerApp] 404 GET /tree? (@172.24.79.160) 1.13ms referer=None
[W 2024-02-21 10:03:58.077 ServerApp] wrote error: 'Forbidden'
    Traceback (most recent call last):
      File "/home/jaalzate/.local/lib/python3.10/site-packages/tornado/web.py", line 1788, in _execute
        result = method(*self.path_args, **self.path_kwargs)
      File "/home/jaalzate/.local/lib/python3.10/site-packages/tornado/web.py", line 3289, in wrapper
        url = self.get_login_url()
      File "/home/jaalzate/.local/lib/python3.10/site-packages/jupyter_server/base/handlers.py", line 763, in get_login_url
        raise web.HTTPError(403)
    tornado.web.HTTPError: HTTP 403: Forbidden
[W 2024-02-21 10:03:58.080 ServerApp] 403 GET /api/kernelspecs?1708506238054 (@172.24.79.160) 4.33ms referer=None
[W 2024-02-21 10:03:58.080 ServerApp] wrote error: 'Forbidden'
    Traceback (most recent call last):
      File "/home/jaalzate/.local/lib/python3.10/site-packages/tornado/web.py", line 1788, in _execute
        result = method(*self.path_args, **self.path_kwargs)
      File "/home/jaalzate/.local/lib/python3.10/site-packages/tornado/web.py", line 3289, in wrapper
        url = self.get_login_url()
      File "/home/jaalzate/.local/lib/python3.10/site-packages/jupyter_server/base/handlers.py", line 763, in get_login_url
        raise web.HTTPError(403)
    tornado.web.HTTPError: HTTP 403: Forbidden
[W 2024-02-21 10:03:58.081 ServerApp] 403 GET /api/kernels?1708506238057 (@172.24.79.160) 5.09ms referer=None
[W 2024-02-21 10:03:58.081 ServerApp] wrote error: 'Forbidden'
    Traceback (most recent call last):
      File "/home/jaalzate/.local/lib/python3.10/site-packages/tornado/web.py", line 1788, in _execute
        result = method(*self.path_args, **self.path_kwargs)
      File "/home/jaalzate/.local/lib/python3.10/site-packages/tornado/web.py", line 3289, in wrapper
        url = self.get_login_url()
      File "/home/jaalzate/.local/lib/python3.10/site-packages/jupyter_server/base/handlers.py", line 763, in get_login_url
        raise web.HTTPError(403)
    tornado.web.HTTPError: HTTP 403: Forbidden
[W 2024-02-21 10:03:58.082 ServerApp] 403 GET /api/kernels?1708506238062 (@172.24.79.160) 5.80ms referer=None
[W 2024-02-21 10:03:58.083 ServerApp] wrote error: 'Forbidden'
    Traceback (most recent call last):
      File "/home/jaalzate/.local/lib/python3.10/site-packages/tornado/web.py", line 1788, in _execute
        result = method(*self.path_args, **self.path_kwargs)
      File "/home/jaalzate/.local/lib/python3.10/site-packages/tornado/web.py", line 3289, in wrapper
        url = self.get_login_url()
      File "/home/jaalzate/.local/lib/python3.10/site-packages/jupyter_server/base/handlers.py", line 763, in get_login_url
        raise web.HTTPError(403)
    tornado.web.HTTPError: HTTP 403: Forbidden
[W 2024-02-21 10:03:58.084 ServerApp] 403 GET /api/sessions?1708506238065 (@172.24.79.160) 1.28ms referer=None
[W 2024-02-21 10:03:58.091 ServerApp] wrote error: 'Forbidden'
    Traceback (most recent call last):
      File "/home/jaalzate/.local/lib/python3.10/site-packages/tornado/web.py", line 1788, in _execute
        result = method(*self.path_args, **self.path_kwargs)
      File "/home/jaalzate/.local/lib/python3.10/site-packages/tornado/web.py", line 3289, in wrapper
        url = self.get_login_url()
      File "/home/jaalzate/.local/lib/python3.10/site-packages/jupyter_server/base/handlers.py", line 763, in get_login_url
        raise web.HTTPError(403)
    tornado.web.HTTPError: HTTP 403: Forbidden
[W 2024-02-21 10:03:58.091 ServerApp] 403 GET /api/kernelspecs?1708506238083 (@172.24.79.160) 1.12ms referer=None
[I 2024-02-21 10:03:58.151 ServerApp] Kernel restarted: 3db022ca-f909-4556-af49-c42e19df514b
[I 2024-02-21 10:04:08.419 ServerApp] User f4a1cd25510d4a888e5f610b4be210b0 logged in.
[I 2024-02-21 10:04:08.420 ServerApp] 302 POST /login? (f4a1cd25510d4a888e5f610b4be210b0@172.24.79.160) 97.15ms
[W 2024-02-21 10:07:26.106 ServerApp] 404 GET /hub/api (@172.24.79.160) 2.92ms referer=None
[I 2024-02-21 10:07:26.380 ServerApp] Kernel started: 6c22dc04-2db2-4005-a4b1-f39dbbe10389
[I 2024-02-21 10:07:27.681 ServerApp] Connecting to kernel 6c22dc04-2db2-4005-a4b1-f39dbbe10389.
[W 2024-02-21 10:07:27.876 ServerApp] 404 GET /hub/api (@172.24.79.160) 14.31ms referer=None
[W 2024-02-21 10:07:27.932 ServerApp] 404 GET /tree? (@172.24.79.160) 12.58ms referer=None
[I 2024-02-21 10:07:31.740 ServerApp] User e4c37dc9c4e74561b19130a32a83077e logged in.
[I 2024-02-21 10:07:31.741 ServerApp] 302 POST /login? (e4c37dc9c4e74561b19130a32a83077e@172.24.79.160) 48.43ms
[I 2024-02-21 10:53:23.594 ServerApp] Kernel restarted: 6c22dc04-2db2-4005-a4b1-f39dbbe10389
[I 2024-02-21 10:53:23.599 ServerApp] Starting buffering for 6c22dc04-2db2-4005-a4b1-f39dbbe10389:66827828-aa88-4dc7-b065-d8d5cce5346c
[I 2024-02-21 10:53:23.611 ServerApp] Connecting to kernel 6c22dc04-2db2-4005-a4b1-f39dbbe10389.
[I 2024-02-21 10:53:23.611 ServerApp] Restoring connection for 6c22dc04-2db2-4005-a4b1-f39dbbe10389:66827828-aa88-4dc7-b065-d8d5cce5346c
HDF5-DIAG: Error detected in HDF5 (1.12.1) thread 0:
  #000: /tmp/SimpleITK-build/ITK/Modules/ThirdParty/HDF5/src/itkhdf5/src/H5Fdeprec.c line 156 in itk_H5Fis_hdf5(): unable to determine if file is accessible as HDF5
    major: File accessibility
    minor: Not an HDF5 file
  #001: /tmp/SimpleITK-build/ITK/Modules/ThirdParty/HDF5/src/itkhdf5/src/H5VLcallback.c line 3769 in itk_H5VL_file_specific(): file specific failed
    major: Virtual Object Layer
    minor: Can't operate on object
  #002: /tmp/SimpleITK-build/ITK/Modules/ThirdParty/HDF5/src/itkhdf5/src/H5VLcallback.c line 3699 in H5VL__file_specific(): file specific failed
    major: Virtual Object Layer
    minor: Can't operate on object
  #003: /tmp/SimpleITK-build/ITK/Modules/ThirdParty/HDF5/src/itkhdf5/src/H5VLnative_file.c line 384 in itk_H5VL__native_file_specific(): error in HDF5 file check
    major: File accessibility
    minor: Unable to initialize object
  #004: /tmp/SimpleITK-build/ITK/Modules/ThirdParty/HDF5/src/itkhdf5/src/H5Fint.c line 1086 in itk_H5F__is_hdf5(): error while trying to locate file signature
    major: File accessibility
    minor: Not an HDF5 file
  #005: /tmp/SimpleITK-build/ITK/Modules/ThirdParty/HDF5/src/itkhdf5/src/H5FDint.c line 113 in itk_H5FD_locate_signature(): unable to read file signature
    major: Low-level I/O
    minor: Unable to initialize object
  #006: /tmp/SimpleITK-build/ITK/Modules/ThirdParty/HDF5/src/itkhdf5/src/H5FDint.c line 189 in itk_H5FD_read(): driver read request failed
    major: Virtual File Layer
    minor: Read failed
  #007: /tmp/SimpleITK-build/ITK/Modules/ThirdParty/HDF5/src/itkhdf5/src/H5FDsec2.c line 755 in H5FD__sec2_read(): file read failed: time = Wed Feb 21 11:08:55 2024
, filename = '/nvmescratch/ceib/Prostate/Bounding_Boxes/p0052021/005586/006040/SEG_20240113_205302_952_S8/SEG', file descriptor = 57, errno = 21, error message = 'Is a directory', buf = 0x7ffe6508b588, total read size = 8, bytes this sub-read = 8, bytes actually read = 18446744073709551615, offset = 0
    major: Low-level I/O
    minor: Read failed
HDF5-DIAG: Error detected in HDF5 (1.12.1) thread 0:
  #000: /tmp/SimpleITK-build/ITK/Modules/ThirdParty/HDF5/src/itkhdf5/src/H5Fdeprec.c line 156 in itk_H5Fis_hdf5(): unable to determine if file is accessible as HDF5
    major: File accessibility
    minor: Not an HDF5 file
  #001: /tmp/SimpleITK-build/ITK/Modules/ThirdParty/HDF5/src/itkhdf5/src/H5VLcallback.c line 3769 in itk_H5VL_file_specific(): file specific failed
    major: Virtual Object Layer
    minor: Can't operate on object
  #002: /tmp/SimpleITK-build/ITK/Modules/ThirdParty/HDF5/src/itkhdf5/src/H5VLcallback.c line 3699 in H5VL__file_specific(): file specific failed
    major: Virtual Object Layer
    minor: Can't operate on object
  #003: /tmp/SimpleITK-build/ITK/Modules/ThirdParty/HDF5/src/itkhdf5/src/H5VLnative_file.c line 384 in itk_H5VL__native_file_specific(): error in HDF5 file check
    major: File accessibility
    minor: Unable to initialize object
  #004: /tmp/SimpleITK-build/ITK/Modules/ThirdParty/HDF5/src/itkhdf5/src/H5Fint.c line 1086 in itk_H5F__is_hdf5(): error while trying to locate file signature
    major: File accessibility
    minor: Not an HDF5 file
  #005: /tmp/SimpleITK-build/ITK/Modules/ThirdParty/HDF5/src/itkhdf5/src/H5FDint.c line 113 in itk_H5FD_locate_signature(): unable to read file signature
    major: Low-level I/O
    minor: Unable to initialize object
  #006: /tmp/SimpleITK-build/ITK/Modules/ThirdParty/HDF5/src/itkhdf5/src/H5FDint.c line 189 in itk_H5FD_read(): driver read request failed
    major: Virtual File Layer
    minor: Read failed
  #007: /tmp/SimpleITK-build/ITK/Modules/ThirdParty/HDF5/src/itkhdf5/src/H5FDsec2.c line 755 in H5FD__sec2_read(): file read failed: time = Wed Feb 21 11:11:52 2024
, filename = '/nvmescratch/ceib/Prostate/Bounding_Boxes/p0052021/005596/006050/SEG_20240113_211223_114_S13001/SEG', file descriptor = 58, errno = 21, error message = 'Is a directory', buf = 0x7ffe6508b588, total read size = 8, bytes this sub-read = 8, bytes actually read = 18446744073709551615, offset = 0
    major: Low-level I/O
    minor: Read failed
HDF5-DIAG: Error detected in HDF5 (1.12.1) thread 0:
  #000: /tmp/SimpleITK-build/ITK/Modules/ThirdParty/HDF5/src/itkhdf5/src/H5Fdeprec.c line 156 in itk_H5Fis_hdf5(): unable to determine if file is accessible as HDF5
    major: File accessibility
    minor: Not an HDF5 file
  #001: /tmp/SimpleITK-build/ITK/Modules/ThirdParty/HDF5/src/itkhdf5/src/H5VLcallback.c line 3769 in itk_H5VL_file_specific(): file specific failed
    major: Virtual Object Layer
    minor: Can't operate on object
  #002: /tmp/SimpleITK-build/ITK/Modules/ThirdParty/HDF5/src/itkhdf5/src/H5VLcallback.c line 3699 in H5VL__file_specific(): file specific failed
    major: Virtual Object Layer
    minor: Can't operate on object
  #003: /tmp/SimpleITK-build/ITK/Modules/ThirdParty/HDF5/src/itkhdf5/src/H5VLnative_file.c line 384 in itk_H5VL__native_file_specific(): error in HDF5 file check
    major: File accessibility
    minor: Unable to initialize object
  #004: /tmp/SimpleITK-build/ITK/Modules/ThirdParty/HDF5/src/itkhdf5/src/H5Fint.c line 1086 in itk_H5F__is_hdf5(): error while trying to locate file signature
    major: File accessibility
    minor: Not an HDF5 file
  #005: /tmp/SimpleITK-build/ITK/Modules/ThirdParty/HDF5/src/itkhdf5/src/H5FDint.c line 113 in itk_H5FD_locate_signature(): unable to read file signature
    major: Low-level I/O
    minor: Unable to initialize object
  #006: /tmp/SimpleITK-build/ITK/Modules/ThirdParty/HDF5/src/itkhdf5/src/H5FDint.c line 189 in itk_H5FD_read(): driver read request failed
    major: Virtual File Layer
    minor: Read failed
  #007: /tmp/SimpleITK-build/ITK/Modules/ThirdParty/HDF5/src/itkhdf5/src/H5FDsec2.c line 755 in H5FD__sec2_read(): file read failed: time = Wed Feb 21 11:16:22 2024
, filename = '/nvmescratch/ceib/Prostate/Bounding_Boxes/p0052021/005596/006050/13001/DICOM', file descriptor = 58, errno = 21, error message = 'Is a directory', buf = 0x7ffe6508b588, total read size = 8, bytes this sub-read = 8, bytes actually read = 18446744073709551615, offset = 0
    major: Low-level I/O
    minor: Read failed
slurmstepd: error: *** JOB 2262632 ON gpuceib01 CANCELLED AT 2024-02-21T12:29:33 ***
